Workbook

Sheet Yuya 2027
A1: Responsable:
A2: Pao Oropeza
CJ15: SEGUIMIENTO DE FECHAS
CJ16: PPEDIDOS | CL16: PREPRODCCION | CN16: AUTORIZACIÓN MARCA | CP16: DISPONIBILIDAD | CR16: DOCUMENTOS PROVEEDOR | CT16: PICK UP DE MERCANCIA | CV16: SALIDA DE LIS | CX16: LLEGADA A ADUANA | CZ16: DISPONIBILIDAD EN ALMACEN
A17: # | B17: Fecha confirmada de Lanzamiento | C17: Mes de Lanzamiento (Esperado) | D17: Estatus | E17: EAN | F17: Código interno | G17: Nombre Comercial | H17: Imagen | I17: Contenido | J17: Marca | K17: Canales | L17: Fase | M17: Costo real (USD) | N17: Moneda | O17: Piezas cotizadas (MOQ) | P17: Costo Esperado en MXN | Q17: IGI | R17: Incrementables | S17: Costo final en MXN (FOB en almacén PT) | T17: Precio Benchmark | U17: Precio publico C/IVA | V17: Facturación por unidad | W17: Factor costo | X17: Margen de utilidad bruta | Y17: MU Cliente | Z17: Categoria | AA17: Pais de origen | AB17: Benchmark | AC17: Comentarios | AD17: Disponibilidad en Almacén | BA17: Line Up | BB17: Costo Autorizado | BC17: PVP Autorizado | BD17: Formula autorizada | BE17: Vobo CEO + VPs | BF17: Arte Final | BG17: PO | BH17: Salida de LIS | BI17: Disponibilidad en almacén | BJ17: Total | BK17: Estatus | BL17: % de Avance | BS17: Comentarios (Qué falta) | BT17: Disponibilidad en almacén | BU17: LIS # | BV17: Responsable Siguiente paso | CJ17: ESPERADA | CK17: REAL | CL17: ESPERADA | CM17: REAL | CN17: ESPERADA | CO17: REAL | CP17: ESPERADA | CQ17: REAL | CR17: ESPERADA | CS17: REAL | CT17: ESPERADA | CU17: REAL | CV17: ESPERADA | CW17: REAL | CX17: ESPERADA | CY17: REAL | CZ17: ESPERADA | DA17: REAL
A18: 33 | B18: TBC | C18: TBC | F18: Y-TC03 | G18: GEL LIMPIADOR FACIAL Y CORPORAL | H18: #VALUE! | I18: 100 mL | J18: Yuya | K18: Multicanal | L18: 1 | N18: MXN | O18: 20000 | P18: 0 | S18: 0 | T18: OGX $148 Tree Hut $178 Dove $294 | U18: 189 | V18: =(U18/1.16)*0.6 -> 97.758621 | W18: =+S18/V18 -> 0 | X18: =1-(S18/V18) -> 1 | Y18: 0.4 | Z18: Color | AA18: MX | AC18: Trabajando en igualación de fragancias. | BA18: 1 | BJ18: 9 | BK18: =SUM(BA18:BI18) -> 1 | BL18: =+BK18/BJ18 -> 0.11111111 | BS18: Autorización de fórmula y fragancia | BT18: =+AD18 -> 0 | BV18: NP
A19: 34 | B19: TBC | C19: TBC | E19: 7506110691594 | F19: Y-SBR01 | G19: Set brochas departamental (10 piezas) | H19: #VALUE! | I19: 10 brochas | J19: Yuya | K19: Multicanal | L19: 1 | N19: USD | O19: 20000 | P19: 0 | R19: 0 | S19: 0 | T19: Beauty Creations $599 Cosmetic Lab $249 ProCore $279 | U19: 899 | V19: =(U19/1.16)*0.6 -> 465 | W19: =+S19/V19 -> 0 | X19: =1-(S19/V19) -> 1 | Y19: 0.4 | Z19: Color | AA19: MX | BA19: 1 | BJ19: 9 | BK19: =SUM(BA19:BI19) -> 1 | BL19: =+BK19/BJ19 -> 0.11111111 | BS19: Elección de brochas del set de 24 | BT19: =+AD19 -> 0 | BV19: Sasu-Ari Glz
A20: 35 | B20: TBC | C20: TBC | E20: 7506110691600 | F20: Y-SBR02 | G20: Set brochas Autoservicio (5 piezas) | H20: #VALUE! | I20: 5 brochas | J20: Yuya | K20: Multicanal | L20: 1 | N20: USD | O20: 20000 | P20: 0 | R20: 0 | S20: 0 | T20: Ecotools $197 Cosmetic Lab $89 Kiss 189.90 Cala $360 | U20: 399 | V20: =(U20/1.16)*0.6 -> 206.37931 | W20: =+S20/V20 -> 0 | X20: =1-(S20/V20) -> 1 | Y20: 0.4 | Z20: Color | AA20: MX | AC20: Stand By | BA20: 1 | BJ20: 9 | BK20: =SUM(BA20:BI20) -> 1 | BL20: =+BK20/BJ20 -> 0.11111111 | BS20: Stand By | BT20: =+AD20 -> 0
A21: 36 | B21: TBC | C21: TBC | F21: Y-GC02 | G21: GEL DE CEJAS DE COLOR MEDIO | H21: #VALUE! | I21: 1.3 mL | J21: Yuya | K21: Multicanal | L21: 1 | N21: MXN | O21: 10000 | P21: 15.99 | S21: 15.99 | T21: NYX $258 Renova $150 Maybelline $239 | U21: 199 | V21: =(U21/1.16)*0.6 -> 102.93103 | W21: =+S21/V21 -> 0.15534673 | X21: =1-(S21/V21) -> 0.84465327 | Y21: 0.4 | AC21: Autorización de tono | BA21: 1 | BJ21: 9 | BK21: =SUM(BA21:BI21) -> 1 | BL21: =+BK21/BJ21 -> 0.11111111 | BS21: Autorización de tono | BT21: =+AD21 -> 0 | BV21: Sasu-Ari Glz
A22: 37 | B22: TBC | C22: TBC | F22: Y-GC03 | G22: GEL DE CEJAS DE COLOR OSCURO | H22: #VALUE! | I22: 1.3 mL | J22: Yuya | K22: Multicanal | L22: 1 | N22: MXN | O22: 10000 | P22: 15.99 | S22: 15.99 | T22: NYX $258 Renova $150 Maybelline $239 | U22: 199 | V22: =(U22/1.16)*0.6 -> 102.93103 | W22: =+S22/V22 -> 0.15534673 | X22: =1-(S22/V22) -> 0.84465327 | Y22: 0.4 | AC22: Autorización de tono | BA22: 1 | BJ22: 9 | BK22: =SUM(BA22:BI22) -> 1 | BL22: =+BK22/BJ22 -> 0.11111111 | BS22: Autorización de tono | BT22: =+AD22 -> 0 | BV22: Sasu-Ari Glz
A23: 38 | B23: TBC | C23: TBC | E23: 7506110694830 | F23: Y-SI01 | G23: SET DE 4 ILUMINADORES EN POLVO | H23: #VALUE! | J23: Yuya | K23: Multicanal | L23: 1 | N23: USD | O23: 20000 | P23: 0 | S23: 0 | T23: Pink Up $689 Milani $188 | U23: 299 | V23: =(U23/1.16)*0.6 -> 154.65517 | W23: =+S23/V23 -> 0 | X23: =1-(S23/V23) -> 1 | Y23: 0.4 | Z23: Color | AA23: MX | BA23: 1 | BJ23: 9 | BK23: =SUM(BA23:BI23) -> 1 | BL23: =+BK23/BJ23 -> 0.11111111 | BS23: Stand By | BT23: =+AD23 -> 0
A24: 39 | B24: TBC | C24: TBC | E24: 7506110694052 | F24: Y-CO01 | G24: Cosmetiquera Departamental 1 | H24: #VALUE! | I24: 1 pieza | J24: Yuya | K24: Multicanal | L24: 1 | M24: 4.2 | N24: USD | O24: 10000 | P24: 75.6 | S24: 90.72 | T24: Beauty Creations $107 Mytagalongs $499 Cloe $549 | U24: 499 | V24: =(U24/1.16)*0.6 -> 258.10345 | W24: =+S24/V24 -> 0.35148697 | X24: =1-(S24/V24) -> 0.64851303 | Y24: 0.3 | BA24: 1 | BJ24: 9 | BK24: =SUM(BA24:BI24) -> 1 | BL24: =+BK24/BJ24 -> 0.11111111 | BS24: Stand By | BT24: =+AD24 -> 0
A25: 40 | B25: TBC | C25: TBC | E25: 7506110694076 | F25: Y-CO03 | G25: Cosmetiquera de Regalo | H25: #VALUE! | I25: 1 pieza | J25: Yuya | K25: Multicanal | L25: 1 | M25: 2 | N25: USD | O25: 10000 | P25: 36 | S25: 43.2 | T25: Miniso $149 Conair $399 Beauty Creations $299 | U25: 229 | V25: =(U25/1.16)*0.6 -> 118.44828 | W25: =+S25/V25 -> 0.36471616 | X25: =1-(S25/V25) -> 0.63528384 | Y25: 0.3 | Z25: Color | AA25: MX | BA25: 1 | BJ25: 9 | BK25: =SUM(BA25:BI25) -> 1 | BL25: =+BK25/BJ25 -> 0.11111111 | BS25: Stand By | BT25: =+AD25 -> 0
A26: 46 | B26: TBC | C26: TBC | E26: 7506110694014 | F26: Y-JB01 | G26: JABON EN BARRA 1 | H26: #VALUE! | I26: 90 g | J26: Yuya | K26: Multicanal | L26: 1 | N26: USD | O26: 20000 | P26: 0 | S26: 0 | T26: Dove $33 Natura $88 Palmolive $23 | U26: 79 | V26: =(U26/1.16)*0.6 -> 40.862069 | W26: =+S26/V26 -> 0 | X26: =1-(S26/V26) -> 1 | Y26: 0.4 | Z26: Color | AA26: MX | BA26: 1 | BJ26: 9 | BK26: =SUM(BA26:BI26) -> 1 | BL26: =+BK26/BJ26 -> 0.11111111 | BT26: =+AD26 -> 0
A27: 47 | B27: TBC | C27: TBC | E27: 7506110694021 | F27: Y-JB02 | G27: JABON EN BARRA 2 | H27: #VALUE! | I27: 90 g | J27: Yuya | K27: Multicanal | L27: 1 | N27: USD | O27: 20000 | P27: 0 | S27: 0 | T27: Dove $33 Natura $88 Palmolive $23 | U27: 79 | V27: =(U27/1.16)*0.6 -> 40.862069 | W27: =+S27/V27 -> 0 | X27: =1-(S27/V27) -> 1 | Y27: 0.4 | Z27: Color | AA27: MX | BA27: 1 | BJ27: 9 | BK27: =SUM(BA27:BI27) -> 1 | BL27: =+BK27/BJ27 -> 0.11111111 | BS27: 0 | BT27: =+AD27 -> 0
A28: 48 | B28: TBC | C28: TBC | F28: Y-CF01 | G28: CREMA FACIAL EN GEL | H28: #VALUE! | I28: 50 g | J28: Yuya | K28: Multicanal | L28: 1 | N28: USD | O28: 20000 | P28: 0 | S28: 0 | T28: Ponds $154 Garnier $119 Ponds $120 | U28: 119 | V28: =(U28/1.16)*0.6 -> 61.551724 | W28: =+S28/V28 -> 0 | X28: =1-(S28/V28) -> 1 | Y28: 0.4 | BA28: 1 | BJ28: 9 | BK28: =SUM(BA28:BI28) -> 1 | BL28: =+BK28/BJ28 -> 0.11111111 | BS28: 0 | BT28: =+AD28 -> 0
A29: 49 | B29: TBC | C29: TBC | G29: PLANCHA ALACIADORA | H29: #VALUE! | I29: 1 pieza | J29: Yuya | K29: Multicanal | L29: 1 | N29: USD | O29: 10000 | P29: 0 | S29: 0 | T29: Revlon $475 Remington $559 Conair $499 | U29: 699 | V29: =(U29/1.16)*0.6 -> 361.55172 | W29: =+S29/V29 -> 0 | X29: =1-(S29/V29) -> 1 | Y29: 0.4 | BA29: 1 | BJ29: 9 | BK29: =SUM(BA29:BI29) -> 1 | BL29: =+BK29/BJ29 -> 0.11111111 | BS29: 0 | BT29: =+AD29 -> 0
A30: 50 | B30: TBC | C30: TBC | G30: CEPILLO SECADOR | H30: #VALUE! | I30: 1 pieza | J30: Yuya | K30: Multicanal | L30: 1 | N30: USD | O30: 10000 | P30: 0 | S30: 0 | T30: Revlon $929 Timco $526 Conair $399 | U30: 599 | V30: =(U30/1.16)*0.6 -> 309.82759 | W30: =+S30/V30 -> 0 | X30: =1-(S30/V30) -> 1 | Y30: 0.4 | BA30: 1 | BJ30: 9 | BK30: =SUM(BA30:BI30) -> 1 | BL30: =+BK30/BJ30 -> 0.11111111 | BS30: 0 | BT30: =+AD30 -> 0
A31: 51 | B31: TBC | C31: TBC | G31: BEAUTY BLENDER | H31: #VALUE! | I31: 1 pieza | J31: Yuya | K31: Multicanal | L31: 1 | M31: 0.42 | N31: USD | O31: 10000 | P31: 7.56 | Q31: 0.5292 | R31: 0.161784 | S31: 8.250984 | T31: Real Techniques $156 Beauty Cretions $56.84 | U31: 599 | V31: =(U31/1.16)*0.6 -> 309.82759 | W31: =+S31/V31 -> 0.026630889 | X31: =1-(S31/V31) -> 0.97336911 | Y31: 0.4 | BA31: 1 | BJ31: 9 | BK31: =SUM(BA31:BI31) -> 1 | BL31: =+BK31/BJ31 -> 0.11111111 | BS31: 0 | BT31: =+AD31 -> 0
A32: 52 | B32: TBC | C32: TBC | F32: Y-SH05 | G32: Shampoo protección calor | K32: Multicanal | L32: 1 | N32: USD | O32: 20002 | P32: 0 | S32: 16.53 | T32: 249 | U32: 89 | V32: =(U32/1.16)*0.6 -> 46.034483 | W32: =+S32/V32 -> 0.35907865 | X32: =1-(S32/V32) -> 0.64092135 | Y32: 0.4 | BA32: 1 | BJ32: 9 | BK32: =SUM(BA32:BI32) -> 1 | BL32: =+BK32/BJ32 -> 0.11111111 | BS32: 0 | BT32: =+AD32 -> 0
A33: 53 | B33: TBC | C33: TBC | F33: Y-SH06 | G33: Shampoo anticaida | K33: Multicanal | L33: 1 | N33: USD | O33: 20003 | P33: 0 | S33: 17.89 | T33: 249 | U33: 89 | V33: =(U33/1.16)*0.6 -> 46.034483 | W33: =+S33/V33 -> 0.38862172 | X33: =1-(S33/V33) -> 0.61137828 | Y33: 0.4 | BA33: 1 | BJ33: 9 | BK33: =SUM(BA33:BI33) -> 1 | BL33: =+BK33/BJ33 -> 0.11111111 | BS33: 0 | BT33: =+AD33 -> 0
A34: 54 | B34: TBC | C34: TBC | F34: Y-AC05 | G34: Acondicionador protección calor | K34: Multicanal | L34: 1 | N34: USD | O34: 20005 | P34: 0 | S34: 17.89 | T34: 249 | U34: 89 | V34: =(U34/1.16)*0.6 -> 46.034483 | W34: =+S34/V34 -> 0.38862172 | X34: =1-(S34/V34) -> 0.61137828 | Y34: 0.4 | BA34: 1 | BJ34: 9 | BK34: =SUM(BA34:BI34) -> 1 | BL34: =+BK34/BJ34 -> 0.11111111 | BS34: 0 | BT34: =+AD34 -> 0
A35: 55 | B35: TBC | C35: TBC | F35: Y-AC06 | G35: Acondicionador anticaida | K35: Multicanal | L35: 1 | N35: USD | O35: 20006 | P35: 0 | S35: 17.89 | T35: 249 | U35: 89 | V35: =(U35/1.16)*0.6 -> 46.034483 | W35: =+S35/V35 -> 0.38862172 | X35: =1-(S35/V35) -> 0.61137828 | Y35: 0.4 | BA35: 1 | BJ35: 9 | BK35: =SUM(BA35:BI35) -> 1 | BL35: =+BK35/BJ35 -> 0.11111111 | BS35: 0 | BT35: =+AD35 -> 0
A36: 56 | B36: TBC | C36: TBC | F36: Y-MC05 | G36: Tratamiento Capilar protección calor | K36: Multicanal | L36: 1 | N36: USD | O36: 20008 | P36: 0 | S36: 15.9 | T36: 249 | U36: 79 | V36: =(U36/1.16)*0.6 -> 40.862069 | W36: =+S36/V36 -> 0.38911392 | X36: =1-(S36/V36) -> 0.61088608 | Y36: 0.4 | BA36: 1 | BJ36: 9 | BK36: =SUM(BA36:BI36) -> 1 | BL36: =+BK36/BJ36 -> 0.11111111 | BS36: 0 | BT36: =+AD36 -> 0
A37: 57 | B37: TBC | C37: TBC | F37: Y-MC06 | G37: Tratamiento Capilar anticaida | K37: Multicanal | L37: 1 | N37: USD | O37: 20009 | P37: 0 | S37: 15.9 | T37: 249 | U37: 79 | V37: =(U37/1.16)*0.6 -> 40.862069 | W37: =+S37/V37 -> 0.38911392 | X37: =1-(S37/V37) -> 0.61088608 | Y37: 0.4 | BA37: 1 | BJ37: 9 | BK37: =SUM(BA37:BI37) -> 1 | BL37: =+BK37/BJ37 -> 0.11111111 | BS37: 0 | BT37: =+AD37 -> 0
A38: 20 | B38: TBC | C38: 46447 | D38: En tiempo | E38: 7506110694786 | F38: Y-G28 | G38: LABIAL LIQUIDO Nueva Formula | H38: #VALUE! | I38: 4 g | J38: Yuya | K38: Multicanal | L38: 1 | M38: 0.98 | N38: USD | O38: 20000 | P38: 17.64 | Q38: 6.3504 | R38: 1.4034384 | S38: 25.393838 | T38: Maybelline $279 Spectra $277 Vixen $145 | U38: 179 | V38: =(U38/1.16)*0.6 -> 92.586207 | W38: =+S38/V38 -> 0.27427237 | X38: =1-(S38/V38) -> 0.72572763 | Y38: 0.4 | Z38: Color | AA38: MX | AC38: Proveedor está proponiendo tonos | AD38: tbc | BA38: 1 | BJ38: 9 | BK38: =SUM(BA38:BI38) -> 1 | BL38: =+BK38/BJ38 -> 0.11111111 | BS38: Viabilidad | BT38: =+AD38 -> tbc | BV38: MKT
A39: 21 | B39: TBC | C39: 46447 | D39: En tiempo | E39: 7506110694793 | F39: Y-G29 | G39: LABIAL LIQUIDO Nueva Formula | H39: #VALUE! | I39: 4 g | J39: Yuya | K39: Multicanal | L39: 1 | M39: 0.98 | N39: USD | O39: 20000 | P39: 17.64 | Q39: 6.3504 | R39: 1.4034384 | S39: 25.393838 | T39: Maybelline $279 Spectra $277 Vixen $145 | U39: 179 | V39: =(U39/1.16)*0.6 -> 92.586207 | W39: =+S39/V39 -> 0.27427237 | X39: =1-(S39/V39) -> 0.72572763 | Y39: 0.4 | Z39: Color | AA39: MX | AC39: Proveedor está proponiendo tonos | AD39: tbc | BA39: 1 | BJ39: 9 | BK39: =SUM(BA39:BI39) -> 1 | BL39: =+BK39/BJ39 -> 0.11111111 | BS39: Viabilidad | BT39: =+AD39 -> tbc | BV39: MKT
A40: 22 | B40: TBC | C40: 46447 | D40: En tiempo | E40: 7506110694809 | F40: Y-G30 | G40: LABIAL LIQUIDO Nueva Formula | H40: #VALUE! | I40: 4 g | J40: Yuya | K40: Multicanal | L40: 1 | M40: 0.98 | N40: USD | O40: 20000 | P40: 17.64 | Q40: 6.3504 | R40: 1.4034384 | S40: 25.393838 | T40: Maybelline $279 Spectra $277 Vixen $145 | U40: 179 | V40: =(U40/1.16)*0.6 -> 92.586207 | W40: =+S40/V40 -> 0.27427237 | X40: =1-(S40/V40) -> 0.72572763 | Y40: 0.4 | Z40: Color | AA40: MX | AC40: Proveedor está proponiendo tonos | AD40: tbc | BA40: 1 | BJ40: 9 | BK40: =SUM(BA40:BI40) -> 1 | BL40: =+BK40/BJ40 -> 0.11111111 | BS40: Viabilidad | BT40: =+AD40 -> tbc | BV40: MKT
A41: 23 | B41: TBC | C41: 46447 | D41: En tiempo | E41: 7506110694816 | F41: Y-G31 | G41: LABIAL LIQUIDO Nueva Formula | H41: #VALUE! | I41: 4 g | J41: Yuya | K41: Multicanal | L41: 1 | M41: 0.98 | N41: USD | O41: 20000 | P41: 17.64 | Q41: 6.3504 | R41: 1.4034384 | S41: 25.393838 | T41: Maybelline $279 Spectra $277 Vixen $145 | U41: 179 | V41: =(U41/1.16)*0.6 -> 92.586207 | W41: =+S41/V41 -> 0.27427237 | X41: =1-(S41/V41) -> 0.72572763 | Y41: 0.4 | Z41: Color | AA41: MX | AC41: Proveedor está proponiendo tonos | AD41: tbc | BA41: 1 | BJ41: 9 | BK41: =SUM(BA41:BI41) -> 1 | BL41: =+BK41/BJ41 -> 0.11111111 | BS41: Viabilidad | BT41: =+AD41 -> tbc | BV41: MKT
A42: 24 | B42: TBC | C42: 46447 | D42: En tiempo | E42: 7506110694823 | F42: Y-G32 | G42: LABIAL LIQUIDO Nueva Formula | H42: #VALUE! | I42: 4 g | J42: Yuya | K42: Multicanal | L42: 1 | M42: 0.98 | N42: USD | O42: 20000 | P42: 17.64 | Q42: 6.3504 | R42: 1.4034384 | S42: 25.393838 | T42: Maybelline $279 Spectra $277 Vixen $145 | U42: 179 | V42: =(U42/1.16)*0.6 -> 92.586207 | W42: =+S42/V42 -> 0.27427237 | X42: =1-(S42/V42) -> 0.72572763 | Y42: 0.4 | Z42: Color | AA42: MX | AC42: Proveedor está proponiendo tonos | AD42: tbc | BA42: 1 | BJ42: 9 | BK42: =SUM(BA42:BI42) -> 1 | BL42: =+BK42/BJ42 -> 0.11111111 | BS42: Viabilidad | BT42: =+AD42 -> tbc | BV42: MKT
A43: 25 | B43: TBC | C43: 46478 | D43: En tiempo | E43: 7506110694830 | F43: Y-LGB01 | G43: LABIAL GLOSS EN BARRA | H43: #VALUE! | J43: Yuya | K43: Multicanal | L43: 1 | N43: USD | O43: 10000 | P43: 0 | Q43: 0 | R43: 0 | S43: 25.39 | T43: NYX $177 ELF $302 Loreal $387 | U43: 179 | V43: =(U43/1.16)*0.6 -> 92.586207 | W43: =+S43/V43 -> 0.27423091 | X43: =1-(S43/V43) -> 0.72576909 | Y43: 0.4 | Z43: Color | AA43: MX | AC43: Proveedor está proponiendo tonos | AD43: tbc | BA43: 1 | BJ43: 9 | BK43: =SUM(BA43:BI43) -> 1 | BL43: =+BK43/BJ43 -> 0.11111111 | BS43: Viabilidad | BT43: =+AD43 -> tbc | BV43: MKT
A44: 26 | B44: TBC | C44: 46478 | D44: En tiempo | F44: Y-LGB02 | G44: LABIAL GLOSS EN BARRA | H44: #VALUE! | J44: Yuya | K44: Multicanal | L44: 1 | N44: USD | O44: 10000 | P44: 0 | Q44: 0 | R44: 0 | S44: 25.39 | U44: 179 | V44: =(U44/1.16)*0.6 -> 92.586207 | W44: =+S44/V44 -> 0.27423091 | X44: =1-(S44/V44) -> 0.72576909 | Y44: 0.4 | AC44: Proveedor está proponiendo tonos | AD44: tbc | BA44: 1 | BJ44: 9 | BK44: =SUM(BA44:BI44) -> 1 | BL44: =+BK44/BJ44 -> 0.11111111 | BS44: Viabilidad | BT44: =+AD44 -> tbc | BV44: MKT
A45: 17 | B45: TBC | C45: 46419 | D45: En tiempo | E45: 7502327992752 | F45: Y-DE2 | G45: BÁLSAMO DESMAQUILLANTE | H45: #VALUE! | I45: 140 g | J45: Yuya | K45: Multicanal | L45: 1 | M45: 1.65 | N45: USD | O45: 20000 | P45: 29.7 | Q45: 7.425 | R45: 2.0010375 | S45: 39.126038 | T45: Beauty Creations $258 L.A Girl $220 Cerave $390 Neutrogena $395 | U45: 259 | V45: =(U45/1.16)*0.6 -> 133.96552 | W45: =+S45/V45 -> 0.29206051 | X45: =1-(S45/V45) -> 0.70793949 | Y45: 0.4 | Z45: Color | AA45: MX | AC45: Render para enviar a autorización en proceso | AD45: 46366 | BA45: 1 | BB45: 1 | BC45: 1 | BD45: 1 | BE45: 1 | BJ45: 9 | BK45: =SUM(BA45:BI45) -> 5 | BL45: =+BK45/BJ45 -> 0.55555556 | BS45: Autorización de render | BT45: =+AD45 -> 46366 | BV45: Sasu-Ari Glz
A46: 10 | B46: TBC | C46: 46388 | D46: En tiempo | E46: 7502327992646 | F46: Y-D01 | G46: Delineador en lápiz negro | H46: #VALUE! | I46: 1.2 g | J46: Yuya | K46: Multicanal | L46: 1 | M46: 18.31 | N46: MXN | O46: 20000 | P46: 18.31 | S46: 18.31 | T46: Revlon $114 NYX $169 Renova $110 | U46: 149 | V46: =(U46/1.16)*0.6 -> 77.068966 | W46: =+S46/V46 -> 0.23757942 | X46: =1-(S46/V46) -> 0.76242058 | Y46: 0.4 | Z46: Color | AA46: MX | AC46: En espera de aprobacion final | AD46: 46329 | BA46: 1 | BB46: 1 | BC46: 1 | BD46: 1 | BE46: 1 | BF46: 1 | BG46: 1 | BJ46: 9 | BK46: =SUM(BA46:BI46) -> 7 | BL46: =+BK46/BJ46 -> 0.77777778 | BS46: Se envío a Yuya para vobo. | BT46: =+AD46 -> 46329 | BV46: Sasu-Ari Glz
A47: 11 | B47: TBC | C47: 46388 | D47: En tiempo | E47: 7502327992653 | F47: Y-D02 | G47: Delineador en lápiz café | H47: #VALUE! | I47: 1.2 g | J47: Yuya | K47: Multicanal | L47: 1 | M47: 18.31 | N47: MXN | O47: 20000 | P47: 18.31 | S47: 18.31 | T47: Revlon $114 NYX $169 Renova $111 | U47: 149 | V47: =(U47/1.16)*0.6 -> 77.068966 | W47: =+S47/V47 -> 0.23757942 | X47: =1-(S47/V47) -> 0.76242058 | Y47: 0.4 | Z47: Color | AA47: MX | AC47: En espera de aprobacion final | AD47: 46329 | BA47: 1 | BB47: 1 | BC47: 1 | BD47: 1 | BE47: 1 | BF47: 1 | BG47: 1 | BJ47: 9 | BK47: =SUM(BA47:BI47) -> 7 | BL47: =+BK47/BJ47 -> 0.77777778 | BS47: Se envío a Yuya para vobo. | BT47: =+AD47 -> 46329 | BV47: Sasu-Ari Glz
A48: 12 | B48: TBC | C48: 46388 | D48: En tiempo | E48: 7502327992660 | F48: Y-D03 | G48: Delineador en lápiz bronce claro | H48: #VALUE! | I48: 1.2 g | J48: Yuya | K48: Multicanal | L48: 1 | M48: 18.31 | N48: MXN | O48: 20000 | P48: 18.31 | S48: 18.31 | T48: Revlon $114 NYX $169 Renova $112 | U48: 149 | V48: =(U48/1.16)*0.6 -> 77.068966 | W48: =+S48/V48 -> 0.23757942 | X48: =1-(S48/V48) -> 0.76242058 | Y48: 0.4 | Z48: Color | AA48: MX | AC48: En espera de aprobacion final | AD48: 46329 | BA48: 1 | BB48: 1 | BC48: 1 | BD48: 1 | BE48: 1 | BF48: 1 | BG48: 1 | BJ48: 9 | BK48: =SUM(BA48:BI48) -> 7 | BL48: =+BK48/BJ48 -> 0.77777778 | BS48: Se envío a Yuya para vobo. | BT48: =+AD48 -> 46329 | BV48: Sasu-Ari Glz
A49: 13 | B49: TBC | C49: 46388 | D49: En tiempo | E49: 7502327992677 | F49: Y-D04 | G49: Delineador en lápiz café - morado | H49: #VALUE! | I49: 1.2 g | J49: Yuya | K49: Multicanal | L49: 1 | M49: 18.31 | N49: MXN | O49: 20000 | P49: 18.31 | S49: 18.31 | T49: Revlon $114 NYX $169 Renova $113 | U49: 149 | V49: =(U49/1.16)*0.6 -> 77.068966 | W49: =+S49/V49 -> 0.23757942 | X49: =1-(S49/V49) -> 0.76242058 | Y49: 0.4 | Z49: Color | AA49: MX | AC49: En espera de aprobacion final | AD49: 46329 | BA49: 1 | BB49: 1 | BC49: 1 | BD49: 1 | BE49: 1 | BF49: 1 | BG49: 1 | BJ49: 9 | BK49: =SUM(BA49:BI49) -> 7 | BL49: =+BK49/BJ49 -> 0.77777778 | BS49: Se envío a Yuya para vobo. | BT49: =+AD49 -> 46329 | BV49: Sasu-Ari Glz
A50: 14 | B50: TBC | C50: 46388 | D50: En tiempo | E50: 7502327992684 | F50: Y-D05 | G50: Delineador en lápiz café nude | H50: #VALUE! | I50: 1.2 g | J50: Yuya | K50: Multicanal | L50: 1 | M50: 18.31 | N50: MXN | O50: 20000 | P50: 18.31 | S50: 18.31 | T50: Revlon $114 NYX $169 Renova $114 | U50: 149 | V50: =(U50/1.16)*0.6 -> 77.068966 | W50: =+S50/V50 -> 0.23757942 | X50: =1-(S50/V50) -> 0.76242058 | Y50: 0.4 | Z50: Color | AA50: MX | AC50: En espera de aprobacion final | AD50: 46329 | BA50: 1 | BB50: 1 | BC50: 1 | BD50: 1 | BE50: 1 | BF50: 1 | BG50: 1 | BJ50: 9 | BK50: =SUM(BA50:BI50) -> 7 | BL50: =+BK50/BJ50 -> 0.77777778 | BS50: Se envío a Yuya para vobo. | BT50: =+AD50 -> 46329 | BV50: Sasu-Ari Glz
A51: 15 | B51: TBC | C51: 46388 | D51: En tiempo | E51: 7502327992691 | F51: Y-D06 | G51: Delineador en lápiz verde olivo | H51: #VALUE! | I51: 1.2 g | J51: Yuya | K51: Multicanal | L51: 1 | M51: 18.31 | N51: MXN | O51: 20000 | P51: 18.31 | S51: 18.31 | T51: Revlon $114 NYX $169 Renova $110 | U51: 149 | V51: =(U51/1.16)*0.6 -> 77.068966 | W51: =+S51/V51 -> 0.23757942 | X51: =1-(S51/V51) -> 0.76242058 | Y51: 0.4 | Z51: Color | AA51: MX | AC51: En espera de aprobacion final | AD51: 46329 | BA51: 1 | BB51: 1 | BC51: 1 | BD51: 1 | BE51: 1 | BF51: 1 | BG51: 1 | BJ51: 9 | BK51: =SUM(BA51:BI51) -> 7 | BL51: =+BK51/BJ51 -> 0.77777778 | BS51: Se envío a Yuya para vobo. | BT51: =+AD51 -> 46329 | BV51: Sasu-Ari Glz

Sheet Yuya 2026
CJ14: SEGUIMIENTO DE FECHAS
CJ15: PPEDIDOS | CL15: PREPRODCCION | CN15: AUTORIZACIÓN MARCA | CP15: DISPONIBILIDAD | CR15: DOCUMENTOS PROVEEDOR | CT15: PICK UP DE MERCANCIA | CV15: SALIDA DE LIS | CX15: LLEGADA A ADUANA | CZ15: DISPONIBILIDAD EN ALMACEN
A16: # | B16: Fecha confirmada de Lanzamiento | C16: Mes de Lanzamiento (Esperado) | D16: Estatus | E16: EAN | F16: Código interno | G16: Nombre Comercial | H16: Imagen | I16: Contenido | J16: Marca | K16: Canales | L16: Fase | M16: Costo real (USD) | N16: Moneda | O16: Piezas cotizadas (MOQ) | P16: Costo Esperado en MXN | Q16: IGI | R16: Incrementables | S16: Costo final en MXN (FOB en almacén PT) | T16: Precio Benchmark | U16: Precio publico C/IVA | V16: Facturación por unidad | W16: Factor costo | X16: Margen de utilidad bruta | Y16: MU Cliente | Z16: Categoria | AA16: Pais de origen | AB16: Benchmark | AC16: Comentarios | AD16: Disponibilidad en Almacén | BA16: Line Up | BB16: Costo Autorizado | BC16: PVP Autorizado | BD16: Formula autorizada | BE16: Vobo CEO + VPs | BF16: Arte Final | BG16: PO | BH16: Salida de LIS | BI16: Disponibilidad en almacén | BJ16: Total | BK16: Estatus | BL16: % de Avance | BS16: Comentarios (Qué falta) | BT16: Disponibilidad en almacén | BU16: LIS # | BV16: Responsable Siguiente paso | CJ16: ESPERADA | CK16: REAL | CL16: ESPERADA | CM16: REAL | CN16: ESPERADA | CO16: REAL | CP16: ESPERADA | CQ16: REAL | CR16: ESPERADA | CS16: REAL | CT16: ESPERADA | CU16: REAL | CV16: ESPERADA | CW16: REAL | CX16: ESPERADA | CY16: REAL | CZ16: ESPERADA | DA16: REAL
A17: 1 | B17: 46044 | C17: Enero | D17: Completado | E17: 7506110695028 | F17: Y-PP02 | G17: PARCHES AUXILIAR PARA GRANITOS ESTRELLAS | H17: #VALUE! | I17: 36 Parches | J17: Yuya | K17: Multicanal | L17: 1 | M17: 0.43 | N17: USD | O17: 30000 | P17: 7.74 | R17: 1.548 | S17: 10.16 | T17: Garnier $150 StarFace $300 | U17: 89 | V17: =(U17/1.16)*0.6 -> 46.034483 | W17: =+S17/V17 -> 0.22070412 | X17: =1-(S17/V17) -> 0.77929588 | Y17: 0.4 | Z17: Color | AA17: CN | AC17: Terminado | AD17: 45992 | BA17: 1 | BB17: 1 | BC17: 1 | BD17: 1 | BE17: 1 | BF17: 1 | BG17: 1 | BH17: 1 | BI17: 1 | BJ17: 9 | BK17: =SUM(BA17:BI17) -> 9 | BL17: =+BK17/BJ17 -> 1 | BS17: Terminado | BT17: =+AD17 -> 45992 | BV17: Comercial | CJ17: 45809 | CK17: 45809 | CL17: =+CJ17+10 -> 45819 | CM17: =+CK17+10 -> 45819 | CN17: =+CL17+14 -> 45833 | CO17: =+CM17+14 -> 45833 | CP17: =+CN17+40 -> 45873 | CQ17: =+CO17+40 -> 45873 | CR17: =+CP17-15 -> 45858 | CT17: =+CP17+7 -> 45880 | CV17: =+CT17+5 -> 45885 | CX17: =+CV17+45 -> 45930 | CZ17: =+CX17+8 -> 45938
A18: 2 | B18: 46044 | C18: Enero | D18: Completado | E18: 7506110695035 | F18: Y-PP03 | G18: PARCHES AUXILIAR PARA GRANITOS CORAZONES | H18: #VALUE! | I18: 24 Parches | J18: Yuya | K18: Multicanal | L18: 1 | M18: 0.43 | N18: USD | O18: 30000 | P18: 7.74 | R18: 1.548 | S18: 10.16 | T18: Garnier $150 StarFace $300 | U18: 89 | V18: =(U18/1.16)*0.6 -> 46.034483 | W18: =+S18/V18 -> 0.22070412 | X18: =1-(S18/V18) -> 0.77929588 | Y18: 0.4 | Z18: Color | AA18: CN | AC18: Terminado | AD18: 45992 | BA18: 1 | BB18: 1 | BC18: 1 | BD18: 1 | BE18: 1 | BF18: 1 | BG18: 1 | BH18: 1 | BI18: 1 | BJ18: 9 | BK18: =SUM(BA18:BI18) -> 9 | BL18: =+BK18/BJ18 -> 1 | BS18: Terminado | BT18: =+AD18 -> 45992 | BV18: Comercial
A19: 3 | B19: 46044 | C19: Enero | D19: Completado | E19: 7506110695042 | F19: Y-PP04 | G19: PARCHES AUXILIAR PARA GRANITOS FLORES CON DIAMANTES | H19: #VALUE! | I19: 24 Parches | J19: Yuya | K19: Multicanal | L19: 1 | M19: 0.77 | N19: USD | O19: 30000 | P19: 13.86 | R19: 2.772 | S19: 18.19 | T19: Garnier $150 StarFace $300 | U19: 139 | V19: =(U19/1.16)*0.6 -> 71.896552 | W19: =+S19/V19 -> 0.2530024 | X19: =1-(S19/V19) -> 0.7469976 | Y19: 0.4 | Z19: Color | AA19: CN | AC19: Terminado | AD19: 45992 | BA19: 1 | BB19: 1 | BC19: 1 | BD19: 1 | BE19: 1 | BF19: 1 | BG19: 1 | BH19: 1 | BI19: 1 | BJ19: 9 | BK19: =SUM(BA19:BI19) -> 9 | BL19: =+BK19/BJ19 -> 1 | BS19: Terminado | BT19: =+AD19 -> 45992 | BV19: Comercial
A20: 4 | C20: Mayo | D20: Completado | F20: Y-SW012 | G20: Set Trío Body Mist Yuya (60 mL) "Jardín Silvestre" | J20: Yuya | S20: 30.98 | U20: 199 | V20: =(U20/1.16)*0.6 -> 102.93103 | W20: =+S20/V20 -> 0.30097822 | X20: =1-(S20/V20) -> 0.69902178 | Y20: 1.4 | Z20: Sets | AA20: MX | AD20: 46143 | BA20: 1 | BB20: 1 | BC20: 1 | BD20: 1 | BE20: 1 | BF20: 1 | BG20: 1 | BH20: 1 | BI20: 1 | BJ20: 9 | BK20: =SUM(BA20:BI20) -> 9 | BL20: =+BK20/BJ20 -> 1 | BS20: Terminado | BT20: =+AD20 -> 46143 | BV20: Comercial
A21: 5 | C21: Mayo | D21: Completado | F21: Y-SW011 | G21: Set Duo Body Mist Yuya (236 mL) "Néctar de Nubes" | J21: Yuya | S21: 57.15 | U21: 290 | V21: =(U21/1.16)*0.6 -> 150 | W21: =+S21/V21 -> 0.381 | X21: =1-(S21/V21) -> 0.619 | Y21: 2.4 | Z21: Sets | AA21: MX | AD21: 46143 | BA21: 1 | BB21: 1 | BC21: 1 | BD21: 1 | BE21: 1 | BF21: 1 | BG21: 1 | BH21: 1 | BI21: 1 | BJ21: 9 | BK21: =SUM(BA21:BI21) -> 9 | BL21: =+BK21/BJ21 -> 1 | BS21: Terminado | BT21: =+AD21 -> 46143 | BV21: Comercial
A22: 6 | C22: Mayo | D22: Completado | F22: Y-SD001 | G22: Jardin Vivo (Máscara para pestañas "10 aceites Naturales + Enchinador "Verde" + Desmaquillante 3 en 1) | J22: Yuya | S22: 72.65 | U22: 459 | V22: =(U22/1.16)*0.6 -> 237.41379 | W22: =+S22/V22 -> 0.30600581 | X22: =1-(S22/V22) -> 0.69399419 | Y22: 3.4 | Z22: Sets | AA22: MX | AD22: 46143 | BA22: 1 | BB22: 1 | BC22: 1 | BD22: 1 | BE22: 1 | BF22: 1 | BG22: 1 | BH22: 1 | BI22: 1 | BJ22: 9 | BK22: =SUM(BA22:BI22) -> 9 | BL22: =+BK22/BJ22 -> 1 | BS22: Terminado | BT22: =+AD22 -> 46143 | BV22: Comercial
C23: Mayo | D23: Completado | F23: Y-SD002 | G23: Alta Frecuencia (Máscara para pestañas "10 aceites Naturales" Negra + Máscara de pestañas Borgoña + Enchinador Borgoña) | J23: Yuya | S23: 67.53 | U23: 499 | V23: =(U23/1.16)*0.6 -> 258.10345 | W23: =+S23/V23 -> 0.26163928 | X23: =1-(S23/V23) -> 0.73836072 | Y23: 4.4 | Z23: Sets | AA23: MX | AD23: 46143 | BA23: 1 | BB23: 1 | BC23: 1 | BD23: 1 | BE23: 1 | BF23: 1 | BG23: 1 | BH23: 1 | BI23: 1 | BJ23: 9 | BK23: =SUM(BA23:BI23) -> 9 | BL23: =+BK23/BJ23 -> 1 | BS23: Terminado | BT23: =+AD23 -> 46143 | BV23: Comercial
C24: Mayo | D24: Completado | F24: Y-SD003 | G24: Ciclo (Máscara 10 aceites negra + Desmaquillante 3 en 1 + Gel para cejas Yuya) | J24: Yuya | S24: 69.93 | U24: 499 | V24: =(U24/1.16)*0.6 -> 258.10345 | W24: =+S24/V24 -> 0.27093788 | X24: =1-(S24/V24) -> 0.72906212 | Y24: 5.4 | Z24: Sets | AA24: MX | AD24: 46143 | BA24: 1 | BB24: 1 | BC24: 1 | BD24: 1 | BE24: 1 | BF24: 1 | BG24: 1 | BH24: 1 | BI24: 1 | BJ24: 9 | BK24: =SUM(BA24:BI24) -> 9 | BL24: =+BK24/BJ24 -> 1 | BS24: Terminado | BT24: =+AD24 -> 46143 | BV24: Comercial
C25: Mayo | D25: Completado | F25: Y-SD004 | G25: Elemental (Máscara para pestañas 10 aceites Yuya + Gel para cejas Yuya) | J25: Yuya | S25: 45.06 | U25: 299 | V25: =(U25/1.16)*0.6 -> 154.65517 | W25: =+S25/V25 -> 0.29135786 | X25: =1-(S25/V25) -> 0.70864214 | Y25: 6.4 | Z25: Sets | AA25: MX | AD25: 46143 | BA25: 1 | BB25: 1 | BC25: 1 | BD25: 1 | BE25: 1 | BF25: 1 | BG25: 1 | BH25: 1 | BI25: 1 | BJ25: 9 | BK25: =SUM(BA25:BI25) -> 9 | BL25: =+BK25/BJ25 -> 1 | BS25: Terminado | BT25: =+AD25 -> 46143 | BV25: Comercial
C26: Mayo | D26: Completado | F26: Y-SD005 | G26: Luz Calida (Máscara para pestañas 10 aceites Yuya + Enchinador Borgoña) | J26: Yuya | S26: 48.59 | U26: 299 | V26: =(U26/1.16)*0.6 -> 154.65517 | W26: =+S26/V26 -> 0.31418283 | X26: =1-(S26/V26) -> 0.68581717 | Y26: 7.4 | Z26: Sets | AA26: MX | AD26: 46143 | BA26: 1 | BB26: 1 | BC26: 1 | BD26: 1 | BE26: 1 | BF26: 1 | BG26: 1 | BH26: 1 | BI26: 1 | BJ26: 9 | BK26: =SUM(BA26:BI26) -> 9 | BL26: =+BK26/BJ26 -> 1 | BS26: Terminado | BT26: =+AD26 -> 46143 | BV26: Comercial
C27: Mayo | D27: Completado | F27: Y-SD006 | G27: Frecuencia (Máscara para pestañas 10 aceites Yuya + Desmaquillante bifásico 10 aceites Yuya) | J27: Yuya | S27: 53.53 | U27: 299 | V27: =(U27/1.16)*0.6 -> 154.65517 | W27: =+S27/V27 -> 0.34612486 | X27: =1-(S27/V27) -> 0.65387514 | Y27: 8.4 | Z27: Sets | AA27: MX | AD27: 46143 | BA27: 1 | BB27: 1 | BC27: 1 | BD27: 1 | BE27: 1 | BF27: 1 | BG27: 1 | BH27: 1 | BI27: 1 | BJ27: 9 | BK27: =SUM(BA27:BI27) -> 9 | BL27: =+BK27/BJ27 -> 1 | BS27: Terminado | BT27: =+AD27 -> 46143 | BV27: Comercial
C28: Mayo | D28: Completado | F28: Y-SD007 | G28: Tres en Loop (Enchinador "Borgoña" + Máscara para pestañas "10 aceites Naturales" negra + Gel para cejas YUYA) | J28: Yuya | S28: 65.33 | U28: 499 | V28: =(U28/1.16)*0.6 -> 258.10345 | W28: =+S28/V28 -> 0.25311556 | X28: =1-(S28/V28) -> 0.74688444 | Y28: 9.4 | Z28: Sets | AA28: MX | AD28: 46143 | BA28: 1 | BB28: 1 | BC28: 1 | BD28: 1 | BE28: 1 | BF28: 1 | BG28: 1 | BH28: 1 | BI28: 1 | BJ28: 9 | BK28: =SUM(BA28:BI28) -> 9 | BL28: =+BK28/BJ28 -> 1 | BS28: Terminado | BT28: =+AD28 -> 46143 | BV28: Comercial
A29: 4 | B29: TBC | C29: Agosto | D29: En tiempo | E29: 7506110691679 | F29: Y-PCC001 | G29: BRUMA PARA CUERPO Y CABELLO "Viento" | H29: #VALUE! | I29: 100 mL | J29: Yuya | K29: Multicanal | L29: 1 | M29: 22.81 | N29: MXN | O29: 35000 | P29: 0 | S29: 22.24 | T29: H6M $199 Grisi $85 Pink Up $118 Red By Kiss $139 | U29: 199 | V29: =(U29/1.16)*0.6 -> 102.93103 | W29: =+S29/V29 -> 0.216067 | X29: =1-(S29/V29) -> 0.783933 | Y29: 0.4 | Z29: Fragancia | AA29: MX/CN | AC29: En Producción | AD29: 46230 | BA29: 1 | BB29: 1 | BC29: 1 | BD29: 1 | BE29: 1 | BF29: 1 | BG29: 1 | BH29: 1 | BI29: 1 | BJ29: 9 | BK29: =SUM(BA29:BI29) -> 9 | BL29: =+BK29/BJ29 -> 1 | BS29: Terminado | BT29: =+AD29 -> 46230 | BV29: Comercial
A30: 5 | B30: TBC | C30: Agosto | D30: En tiempo | E30: 7506110691686 | F30: Y-PCC002 | G30: BRUMA PARA CUERPO Y CABELLO "Mango Luna" | H30: #VALUE! | I30: 100 mL | J30: Yuya | K30: Multicanal | L30: 1 | M30: 22.95 | N30: MXN | O30: 35000 | P30: 0 | S30: 22.4 | T30: H6M $199 Grisi $85 Pink Up $94 Red By Kiss $139 | U30: 199 | V30: =(U30/1.16)*0.6 -> 102.93103 | W30: =+S30/V30 -> 0.21762144 | X30: =1-(S30/V30) -> 0.78237856 | Y30: 0.4 | Z30: Fragancia | AA30: MX/CN | AC30: En Producción | AD30: 46230 | BA30: 1 | BB30: 1 | BC30: 1 | BD30: 1 | BE30: 1 | BF30: 1 | BG30: 1 | BH30: 1 | BI30: 1 | BJ30: 9 | BK30: =SUM(BA30:BI30) -> 9 | BL30: =+BK30/BJ30 -> 1 | BS30: Terminado | BT30: =+AD30 -> 46230 | BV30: Comercial
A31: 6 | B31: TBC | C31: Agosto | D31: En tiempo | E31: 7506110693925 | F31: Y-PCC003 | G31: BRUMA PARA CUERPO Y CABELLO "Vainilla Boreal" | H31: #VALUE! | I31: 100 mL | J31: Yuya | K31: Multicanal | L31: 1 | M31: 23.64 | N31: MXN | O31: 35000 | P31: 0 | S31: 22.76 | T31: H6M $199 Grisi $85 Pink Up $94 Red By Kiss $139 | U31: 199 | V31: =(U31/1.16)*0.6 -> 102.93103 | W31: =+S31/V31 -> 0.22111893 | X31: =1-(S31/V31) -> 0.77888107 | Y31: 0.4 | Z31: Fragancia | AA31: MX/CN | AC31: En Producción | AD31: 46230 | BA31: 1 | BB31: 1 | BC31: 1 | BD31: 1 | BE31: 1 | BF31: 1 | BG31: 1 | BH31: 1 | BI31: 1 | BJ31: 9 | BK31: =SUM(BA31:BI31) -> 9 | BL31: =+BK31/BJ31 -> 1 | BS31: Terminado | BT31: =+AD31 -> 46230 | BV31: Comercial
A32: 7 | B32: TBC | C32: Agosto | D32: En tiempo | E32: 7506110693932 | F32: Y-PCC004 | G32: BRUMA PARA CUERPO Y CABELLO "Bruma tropical" | H32: #VALUE! | I32: 100 mL | J32: Yuya | K32: Multicanal | L32: 1 | M32: 23.57 | N32: MXN | O32: 35000 | P32: 0 | S32: 22.62 | T32: H6M $199 Grisi $85 Pink Up $94 Red By Kiss $139 | U32: 199 | V32: =(U32/1.16)*0.6 -> 102.93103 | W32: =+S32/V32 -> 0.21975879 | X32: =1-(S32/V32) -> 0.78024121 | Y32: 0.4 | Z32: Fragancia | AA32: MX/CN | AC32: En Producción | AD32: 46230 | BA32: 1 | BB32: 1 | BC32: 1 | BD32: 1 | BE32: 1 | BF32: 1 | BG32: 1 | BH32: 1 | BI32: 1 | BJ32: 9 | BK32: =SUM(BA32:BI32) -> 9 | BL32: =+BK32/BJ32 -> 1 | BS32: Terminado | BT32: =+AD32 -> 46230 | BV32: Comercial
A33: 8 | B33: TBC | C33: JULIO | D33: En tiempo | E33: 7502327990765 | F33: Y-REP01 | G33: Repuestos Enchinador Borgoña | I33: 3 repuestos | J33: Yuya | K33: Multicanal | L33: 1 | M33: 0.17 | N33: USD | O33: 25000 | P33: =M33*18.5 -> 3.145 | R33: 0.1053 | S33: 3.5 | T33: By Apple $35 Shiseido $200 | U33: 59 | V33: =(U33/1.16)*0.6 -> 30.517241 | W33: =+S33/V33 -> 0.11468927 | X33: =1-(S33/V33) -> 0.88531073 | Y33: 0.4 | Z33: Color | AA33: MX | AC33: En Producción | AD33: 46207 | BA33: 1 | BB33: 1 | BC33: 1 | BD33: 1 | BE33: 1 | BF33: 1 | BG33: 1 | BH33: 1 | BI33: 1 | BJ33: 9 | BK33: =SUM(BA33:BI33) -> 9 | BL33: =+BK33/BJ33 -> 1 | BS33: Terminado | BT33: =+AD33 -> 46207 | BV33: Comercial
A34: 9 | B34: TBC | C34: JULIO | D34: En tiempo | E34: 7502327990772 | F34: Y-REP02 | G34: Repuestos Enchinador Verde | I34: 3 repuestos | J34: Yuya | K34: Multicanal | L34: 1 | M34: 0.17 | N34: USD | O34: 15000 | P34: =M34*18.5 -> 3.145 | R34: 0.1053 | S34: 3.5 | T34: By Apple $35 Shiseido $200 | U34: 59 | V34: =(U34/1.16)*0.6 -> 30.517241 | W34: =+S34/V34 -> 0.11468927 | X34: =1-(S34/V34) -> 0.88531073 | Y34: 0.4 | Z34: Color | AA34: MX | AC34: En Producción | AD34: 46207 | BA34: 1 | BB34: 1 | BC34: 1 | BD34: 1 | BE34: 1 | BF34: 1 | BG34: 1 | BH34: 1 | BI34: 1 | BJ34: 9 | BK34: =SUM(BA34:BI34) -> 9 | BL34: =+BK34/BJ34 -> 1 | BS34: Terminado | BT34: =+AD34 -> 46207 | BV34: Comercial
A35: 16 | B35: TBC | C35: Septiembre | D35: En tiempo | E35: 7506110694854 | F35: Y-TC01 | G35: Aceite Capilar 10 Aceites | I35: 100 mL | J35: Yuya | K35: Multicanal | L35: 1 | M35: 27.46 | N35: MXN | O35: 10000 | S35: 26.59 | T35: Elvive $195 Biometik $133 Dove $149 OGX $149 | U35: 195 | V35: =(U35/1.16)*0.6 -> 100.86207 | W35: =+S35/V35 -> 0.26362735 | X35: =1-(S35/V35) -> 0.73637265 | Y35: 0.4 | Z35: Color | AA35: MX | AC35: Orden de Compra | AD35: 46282 | BA35: 1 | BB35: 1 | BC35: 1 | BD35: 1 | BE35: 1 | BF35: 1 | BG35: 1 | BH35: 1 | BJ35: 9 | BK35: =SUM(BA35:BI35) -> 8 | BL35: =+BK35/BJ35 -> 0.88888889 | BS35: Terminado | BT35: =+AD35 -> 46282 | BV35: Comercial
A36: 18 | B36: TBC | C36: OCTUBRE | D36: En tiempo | E36: 7502327992707 | F36: Y-SM04 | G36: Paleta de Sombras Metalizada Órbita | H36: #VALUE! | I36: 12.6 g | J36: Yuya | K36: Multicanal | L36: 1 | N36: USD | O36: 20000 | P36: 0 | S36: 45.89 | T36: 295 | U36: 299 | V36: =(U36/1.16)*0.6 -> 154.65517 | W36: =+S36/V36 -> 0.29672464 | X36: =1-(S36/V36) -> 0.70327536 | Y36: 0.4 | Z36: Color | AA36: MX | AC36: Falta autorización en renders. Falta autorizar 2 tonos. | AD36: 46320 | BA36: 1 | BB36: 1 | BC36: 1 | BD36: 1 | BE36: 1 | BF36: 1 | BG36: 1 | BH36: 1 | BJ36: 9 | BK36: =SUM(BA36:BI36) -> 8 | BL36: =+BK36/BJ36 -> 0.88888889 | BS36: Salió el envío marítimo | BT36: =+AD36 -> 46320 | BV36: Logística
A37: 19 | B37: TBC | C37: OCTUBRE | D37: En tiempo | E37: 7502327992714 | F37: Y-SM05 | G37: Paleta de Sombras Metalizada Desvelo | H37: #VALUE! | I37: 12.6 g | J37: Yuya | K37: Multicanal | L37: 1 | N37: USD | O37: 20000 | P37: 0 | S37: 45.89 | T37: 295 | U37: 299 | V37: =(U37/1.16)*0.6 -> 154.65517 | W37: =+S37/V37 -> 0.29672464 | X37: =1-(S37/V37) -> 0.70327536 | Y37: 0.4 | Z37: Color | AA37: MX | AC37: Falta autorización en renders. Falta autorizar 2 tonos. | AD37: 46320 | BA37: 1 | BB37: 1 | BC37: 1 | BD37: 1 | BE37: 1 | BF37: 1 | BG37: 1 | BH37: 1 | BJ37: 9 | BK37: =SUM(BA37:BI37) -> 8 | BL37: =+BK37/BJ37 -> 0.88888889 | BS37: Salió el envío marítimo | BT37: =+AD37 -> 46320 | BV37: Logística
A38: 28 | B38: TBC | C38: Noviembre | D38: En tiempo | F38: Y-CA02 | G38: CALENDARIO DE ADVIENTO | H38: #VALUE! | I38: 1 caja + 12 regalos | J38: Yuya | K38: Multicanal | L38: 1 | N38: USD | O38: 20000 | P38: 0 | S38: 314.71 | U38: 1599 | V38: =(U38/1.16)*0.6 -> 827.06897 | W38: =+S38/V38 -> 0.3805124 | X38: =1-(S38/V38) -> 0.6194876 | Y38: 0.4 | Z38: Color | AA38: MX | AC38: Confirmación de costos con Arturo | AD38: 46335 | BA38: 1 | BB38: 1 | BC38: 1 | BD38: 1 | BE38: 1 | BF38: 1 | BG38: 1 | BH38: 1 | BJ38: 9 | BK38: =SUM(BA38:BI38) -> 8 | BL38: =+BK38/BJ38 -> 0.88888889 | BS38: Salió el envío marítimo | BT38: =+AD38 -> 46335 | BV38: Logística
C39: SEPTIEMBRE | D39: En tiempo | E39: 7506110696704 | F39: Y-SD008 | G39: Trilogía Máscara 10 Aceites Esenciales Negra+ Máscara 10 Aceites Café + Gel Fijador para Cejas | H39: #VALUE! | I39: 19 g | J39: Yuya | K39: Yuya | L39: Yuya | M39: Yuya | N39: Yuya | O39: Yuya | P39: Yuya | Q39: Yuya | R39: Yuya | S39: 59.86 | U39: 499 | V39: =(U39/1.16)*0.6 -> 258.10345 | W39: =+S39/V39 -> 0.23192251 | X39: =1-(S39/V39) -> 0.76807749 | Y39: 0.4 | Z39: Color | AA39: MX | AC39: Falta autorización de espejo | AD39: 46279 | BA39: 1 | BB39: 1 | BC39: 1 | BD39: 1 | BE39: 1 | BF39: 1 | BG39: 1 | BH39: 1 | BJ39: 9 | BK39: =SUM(BA39:BI39) -> 8 | BL39: =+BK39/BJ39 -> 0.88888889 | BS39: Terminado | BT39: =+AD39 -> 46279 | BV39: Comercial
C40: DICIEMBRE | D40: En tiempo | E40: 7506110696711 | F40: Y-SD009 | G40: Un segundo Tinta Multiusos Yin Yang+ Enchinador Verde Máscara 10 Aceites Esenciales Negra+ Espejo | J40: Yuya | K40: Yuya | L40: Yuya | M40: Yuya | N40: Yuya | O40: Yuya | P40: Yuya | Q40: Yuya | R40: Yuya | S40: 93.76 | U40: 499 | V40: =(U40/1.16)*0.6 -> 258.10345 | W40: =+S40/V40 -> 0.3632652 | X40: =1-(S40/V40) -> 0.6367348 | Y40: 1.4 | AA40: MX | AD40: 46286 | BA40: 1 | BB40: 1 | BC40: 1 | BD40: 1 | BE40: 1 | BF40: 1 | BG40: 1 | BH40: 1 | BJ40: 9 | BK40: =SUM(BA40:BI40) -> 8 | BL40: =+BK40/BJ40 -> 0.88888889 | BS40: Terminado | BT40: =+AD40 -> 46286 | BV40: Comercial
C41: SEPTIEMBRE | D41: En tiempo | E41: 7506110696728 | F41: Y-SD010 | G41: Tres momentos Máscara 10 Aceites Esenciales Negra+ Polvo Traslúcido + Gel Fijador para Cejas + Beauty Blender | J41: Yuya | K41: Yuya | L41: Yuya | M41: Yuya | N41: Yuya | O41: Yuya | P41: Yuya | Q41: Yuya | R41: Yuya | S41: 85.18 | U41: 599 | V41: =(U41/1.16)*0.6 -> 309.82759 | W41: =+S41/V41 -> 0.2749271 | X41: =1-(S41/V41) -> 0.7250729 | Y41: 2.4 | AA41: MX | AD41: 46279 | BA41: 1 | BB41: 1 | BC41: 1 | BD41: 1 | BE41: 1 | BF41: 1 | BG41: 1 | BH41: 1 | BJ41: 9 | BK41: =SUM(BA41:BI41) -> 8 | BL41: =+BK41/BJ41 -> 0.88888889 | BS41: Terminado | BT41: =+AD41 -> 46279 | BV41: Comercial
C42: SEPTIEMBRE | D42: En tiempo | E42: 7506110696735 | F42: Y-SD011 | G42: Todo Bien Parche Auxiliar para Granitos + Tratamiento Chau Granitos + Papel Arroz Serendipia | J42: Yuya | K42: Yuya | L42: Yuya | M42: Yuya | N42: Yuya | O42: Yuya | P42: Yuya | Q42: Yuya | R42: Yuya | S42: 55.04 | U42: 349 | V42: =(U42/1.16)*0.6 -> 180.51724 | W42: =+S42/V42 -> 0.30490162 | X42: =1-(S42/V42) -> 0.69509838 | Y42: 3.4 | AA42: MX | AD42: 46279 | BA42: 1 | BB42: 1 | BC42: 1 | BD42: 1 | BE42: 1 | BF42: 1 | BG42: 1 | BH42: 1 | BJ42: 9 | BK42: =SUM(BA42:BI42) -> 8 | BL42: =+BK42/BJ42 -> 0.88888889 | BS42: Terminado | BT42: =+AD42 -> 46279 | BV42: Comercial
C43: SEPTIEMBRE | D43: En tiempo | E43: 7506110696742 | F43: Y-SD012 | G43: Dual Máscara 10 Aceites Esenciales Negra+ Máscara 10 Aceites Borgoña | J43: Yuya | K43: Yuya | L43: Yuya | M43: Yuya | N43: Yuya | O43: Yuya | P43: Yuya | Q43: Yuya | R43: Yuya | S43: 42.48 | U43: 329 | V43: =(U43/1.16)*0.6 -> 170.17241 | W43: =+S43/V43 -> 0.24962918 | X43: =1-(S43/V43) -> 0.75037082 | Y43: 4.4 | AA43: MX | AD43: 46279 | BA43: 1 | BB43: 1 | BC43: 1 | BD43: 1 | BE43: 1 | BF43: 1 | BG43: 1 | BH43: 1 | BJ43: 9 | BK43: =SUM(BA43:BI43) -> 8 | BL43: =+BK43/BJ43 -> 0.88888889 | BS43: Terminado | BT43: =+AD43 -> 46279 | BV43: Comercial
C44: SEPTIEMBRE | D44: En tiempo | E44: 7506110696766 | F44: Y-SD014 | G44: Entre lirios Máscara 10 Aceites Esenciales Negra+ Blush Pequeño Lirio | J44: Yuya | K44: Yuya | L44: Yuya | M44: Yuya | N44: Yuya | O44: Yuya | P44: Yuya | Q44: Yuya | R44: Yuya | S44: 35.69 | U44: 299 | V44: =(U44/1.16)*0.6 -> 154.65517 | W44: =+S44/V44 -> 0.23077146 | X44: =1-(S44/V44) -> 0.76922854 | Y44: 5.4 | AA44: MX | AD44: 46279 | BA44: 1 | BB44: 1 | BC44: 1 | BD44: 1 | BE44: 1 | BF44: 1 | BG44: 1 | BH44: 1 | BJ44: 9 | BK44: =SUM(BA44:BI44) -> 8 | BL44: =+BK44/BJ44 -> 0.88888889 | BS44: Terminado | BT44: =+AD44 -> 46279 | BV44: Comercial
C45: SEPTIEMBRE | D45: En tiempo | E45: 7506110696780 | F45: Y-SW013 | G45: Jardín Secreto Trio Body Mist | J45: Yuya | K45: Yuya | L45: Yuya | M45: Yuya | N45: Yuya | O45: Yuya | P45: Yuya | Q45: Yuya | R45: Yuya | S45: 31.25 | U45: 199 | V45: =(U45/1.16)*0.6 -> 102.93103 | W45: =+S45/V45 -> 0.30360134 | X45: =1-(S45/V45) -> 0.69639866 | Y45: 6.4 | AA45: MX | AD45: 46279 | BA45: 1 | BB45: 1 | BC45: 1 | BD45: 1 | BE45: 1 | BF45: 1 | BG45: 1 | BH45: 1 | BJ45: 9 | BK45: =SUM(BA45:BI45) -> 8 | BL45: =+BK45/BJ45 -> 0.88888889 | BS45: Terminado | BT45: =+AD45 -> 46279 | BV45: Comercial
C46: SEPTIEMBRE | D46: En tiempo | E46: 7506110696797 | F46: Y-SW014 | G46: Pedazo de Cielo Duo Body mist | J46: Yuya | K46: Yuya | L46: Yuya | M46: Yuya | N46: Yuya | O46: Yuya | P46: Yuya | Q46: Yuya | R46: Yuya | S46: 49.97 | U46: 299 | V46: =(U46/1.16)*0.6 -> 154.65517 | W46: =+S46/V46 -> 0.32310591 | X46: =1-(S46/V46) -> 0.67689409 | Y46: 7.4 | AA46: MX | AD46: 46279 | BA46: 1 | BB46: 1 | BC46: 1 | BD46: 1 | BE46: 1 | BF46: 1 | BG46: 1 | BH46: 1 | BJ46: 9 | BK46: =SUM(BA46:BI46) -> 8 | BL46: =+BK46/BJ46 -> 0.88888889 | BS46: Terminado | BT46: =+AD46 -> 46279 | BV46: Comercial
A47: 41 | B47: TBC | C47: 46388 | D47: En tiempo | E47: 7502327992769 | F47: Y-SH04 | G47: Shampoo Nuevo | H47: #VALUE! | I47: 1 pieza | J47: Yuya | K47: Multicanal | L47: 1 | N47: USD | O47: 20000 | P47: 16.88 | S47: 24.98 | T47: Elvive $85 Sedal $85 Grisi $85 | U47: 89 | V47: =(U47/1.16)*0.6 -> 46.034483 | W47: =+S47/V47 -> 0.5426367 | X47: =1-(S47/V47) -> 0.4573633 | Y47: 0.4 | AA47: MX | AC47: Falta autorización de fórmula y fragancia | AD47: Diciembre | BA47: 1 | BB47: 1 | BC47: 1 | BE47: 1 | BJ47: 9 | BK47: =SUM(BA47:BI47) -> 4 | BL47: =+BK47/BJ47 -> 0.44444444 | BS47: Prueblas de eficacia | BT47: Enero | BV47: NP
A48: 42 | B48: TBC | C48: 46388 | D48: En tiempo | E48: 7502327992776 | F48: Y-AC04 | G48: Acondicionador Nuevo | H48: #VALUE! | I48: 1 pieza | J48: Yuya | K48: Multicanal | L48: 1 | N48: USD | O48: 20000 | P48: 16.88 | S48: 26.23 | T48: Loreal $85 Sedal $85 Ann Rottshiel $103 | U48: 89 | V48: =(U48/1.16)*0.6 -> 46.034483 | W48: =+S48/V48 -> 0.56979026 | X48: =1-(S48/V48) -> 0.43020974 | Y48: 0.4 | AA48: MX | AC48: Falta autorización de fórmula y fragancia | AD48: Diciembre | BA48: 1 | BB48: 1 | BC48: 1 | BE48: 1 | BJ48: 9 | BK48: =SUM(BA48:BI48) -> 4 | BL48: =+BK48/BJ48 -> 0.44444444 | BS48: Prueblas de eficacia | BT48: Enero | BV48: NP
A49: 43 | B49: TBC | C49: 46388 | D49: En tiempo | E49: 7502327992783 | F49: Y-MC04 | G49: Tratamiento Capilar Nuevo | H49: #VALUE! | I49: 1 pieza | J49: Yuya | K49: Multicanal | L49: 1 | N49: USD | O49: 20000 | P49: 16.88 | S49: 23.44 | T49: Neffertiti $146 Sedal $64 Elvive $101 | U49: 79 | V49: =(U49/1.16)*0.6 -> 40.862069 | W49: =+S49/V49 -> 0.57363713 | X49: =1-(S49/V49) -> 0.42636287 | Y49: 0.4 | AA49: MX | AC49: Falta autorización de fórmula y fragancia | AD49: Diciembre | BA49: 1 | BB49: 1 | BC49: 1 | BE49: 1 | BJ49: 9 | BK49: =SUM(BA49:BI49) -> 4 | BL49: =+BK49/BJ49 -> 0.44444444 | BS49: Prueblas de eficacia | BT49: Enero | BV49: NP
BL50: =AVERAGE(BL17:BL49) -> 0.90909091

Sheet Velvet 2026 Fase 1
B1: Estatus | C1: Atrasado
A2: Velvet
A3: Agencia | B3: 46113 | C3: 46133
A4: Autorizacion | B4: =+B3+2 -> 46115 | C4: =+C3+2 -> 46135
A5: Diseño final | B5: =+B4+7 -> 46122 | C5: =+C4+7 -> 46142
A6: Autorizaciones | B6: =+B5+5 -> 46127 | C6: =+C5+5 -> 46147
A7: Orden de compra | B7: =+B6+2 -> 46129 | C7: =+C6+2 -> 46149
A8: Fecha Estimada Pago balance | B8: =+B7+45 -> 46174 | C8: =+C7+45 -> 46194
A9: Produccion / envio | B9: =+B7+40 -> 46169 | C9: =+C7+40 -> 46189
A10: Llegada Almacén | B10: =+B9+65 -> 46234 | C10: =+C9+65 -> 46254
A11: Lanzamiento | B11: =+B10+14 -> 46248 | C11: =+C10+14 -> 46268
CJ14: SEGUIMIENTO DE FECHAS
S15: 2.62 | AL15: MEGAOUTLET | BA15: % AVANCE POR PRODUCTOS | CJ15: PPEDIDOS | CL15: PREPRODCCION | CN15: AUTORIZACIÓN MARCA | CP15: DISPONIBILIDAD | CR15: DOCUMENTOS PROVEEDOR | CT15: PICK UP DE MERCANCIA | CV15: SALIDA DE LIS | CX15: LLEGADA A ADUANA | CZ15: DISPONIBILIDAD EN ALMACEN
A16: # | B16: Fecha confirmada de Lanzamiento | C16: Mes de Lanzamiento (Esperado) | D16: Estatus | E16: EAN | F16: Código interno | G16: Nombre Comercial | H16: Imagen | I16: Contenido | J16: Marca | K16: Canales | L16: Fase | M16: Proveedor | N16: Benchmark tonos Amazon/MELI | O16: Categoría | P16: Costo real | Q16: Moneda | R16: Piezas cotizadas (MOQ) | S16: Costo Esperado en MXN | T16: IGI | U16: Incrementables | V16: Costo final en MXN (FOB en almacén PT) | W16: Precio publico C/IVA | X16: Precio Público S/IVA | Y16: Facturación por unidad | Z16: Factor costo | AA16: Margen de utilidad bruta | AB16: MU Cliente | AC16: Pais de Origen | AD16: DUN 14 (INNER) | AE16: Inner | AF16: Master | AG16: Comentarios | AH16: Disponibilidad en Almacén | AL16: Precio publico C/IVA | AM16: Facturación por unidad | AN16: Factor costo | AO16: Margen de utilidad bruta | AP16: Margen MO | BA16: Definición del Line Up | BB16: Costo / PVP Autorizado | BC16: PVP Autorizado | BD16: Colores y formula autorizada | BE16: Vobo CEO + VPs | BF16: Arte Final (Diseño) | BG16: PO | BH16: Salida de LIS | BI16: Disponibilidad en almacén | BJ16: Total | BK16: Estatus | BL16: % de Avance | BR16: Comentarios | BS16: Disponibilidad en Almacén | BT16: Responsable Siguiente paso | CJ16: ESPERADA | CK16: REAL | CL16: ESPERADA | CM16: REAL | CN16: ESPERADA | CO16: REAL | CP16: ESPERADA | CQ16: REAL | CR16: ESPERADA | CS16: REAL | CT16: ESPERADA | CU16: REAL | CV16: ESPERADA | CW16: REAL | CX16: ESPERADA | CY16: REAL | CZ16: ESPERADA | DA16: REAL
A17: 1 | B17: TBC | C17: Diciembre | D17: En tiempo | E17: 7502327990857 | F17: VLT-01 | G17: Base de Maquillaje Velvet "Smooth Foundation - CN1" | H17: #VALUE! | I17: 50 mL | J17: Velvet | K17: Mix de canales | L17: 1 | M17: MUC | N17: https://www.maccosmetics.com.mx/product/13847/119586/productos/maquillaje/rostro/bases-de-maquillaje/studio-radiance-serum-poweredtm-foundation?shade=NC15 | O17: MAKEUP | P17: 6.95 | Q17: RMB | R17: 10000 | S17: =P17*S15 -> 18.209 | T17: =+S17*0.25 -> 4.55225 | U17: =(S17+T17)*0.044 -> 1.001495 | V17: =S17+T17+U17 -> 23.762745 | W17: 249 | X17: =W17/1.16 -> 214.65517 | Y17: =X17*0.6 -> 128.7931 | Z17: =V17/Y17 -> 0.18450324 | AA17: =1-(V17/Y17) -> 0.81549676 | AB17: =1-(Y17/(W17/1.16)) -> 0.4 | AC17: China | AE17: 6 | AF17: 48 | AG17: En revisión de dummy para autorización final | AH17: 46341 | AL17: 161.85 | AM17: =+AL17/1.16 -> 139.52586 | AN17: =+V18/AM17 -> #VALUE! | AO17: =1-V18/AM17 -> #VALUE! | AP17: =1-(AM17/(AL17/1.16)) -> 0 | BA17: 1 | BB17: 1 | BC17: 1 | BD17: 1 | BE17: 1 | BF17: 1 | BG17: 1 | BJ17: 9 | BK17: =SUM(BA17:BI17) -> 7 | BL17: =+BK17/BJ17 -> 0.77777778 | BR17: PPEDIDOS-260727498 Se espera que PT este listo 30 Sept | BS17: 46376 | BT17: Eduardo (Compras) | CJ17: 46188
A18: 2 | B18: TBC | C18: Diciembre | D18: En tiempo | E18: 7502327990864 | F18: VLT-02 | G18: Base de Maquillaje Velvet "Smooth Foundation - CC2" | H18: #VALUE! | I18: 50 mL | J18: Velvet | K18: Mix de canales | L18: 1 | M18: MUC | N18: https://www.maccosmetics.com.mx/product/13847/119586/productos/maquillaje/rostro/bases-de-maquillaje/studio-radiance-serum-poweredtm-foundation?shade=NW2 | O18: MAKEUP | P18: 6.95 | Q18: RMB | R18: 10000 | S18: =+P18*$T$29 -> #VALUE! | T18: =+S18*0.25 -> #VALUE! | U18: =(S18+T18)*0.044 -> #VALUE! | V18: =S18+T18+U18 -> #VALUE! | W18: 249 | X18: =W18/1.16 -> 214.65517 | Y18: =X18*0.6 -> 128.7931 | Z18: =V18/Y18 -> #VALUE! | AA18: =1-(V18/Y18) -> #VALUE! | AB18: =1-(Y18/(W18/1.16)) -> 0.4 | AC18: China | AE18: 6 | AF18: 48 | AG18: En revisión de dummy para autorización final | AH18: 46341 | AL18: 161.85 | AM18: =+AL18/1.16 -> 139.52586 | AN18: =+V19/AM18 -> #VALUE! | AO18: =1-V19/AM18 -> #VALUE! | AP18: =1-(AM18/(AL18/1.16)) -> 0 | BA18: 1 | BB18: 1 | BC18: 1 | BD18: 1 | BE18: 1 | BF18: 1 | BG18: 1 | BJ18: 9 | BK18: =SUM(BA18:BI18) -> 7 | BL18: =+BK18/BJ18 -> 0.77777778 | BR18: PPEDIDOS-260727498 Se espera que PT este listo 30 Sept | BS18: 46376 | BT18: Eduardo (Compras) | CJ18: 46188
A19: 3 | B19: TBC | C19: Diciembre | D19: En tiempo | E19: 7502327990871 | F19: VLT-03 | G19: Base de Maquillaje Velvet "Smooth Foundation - CC3" | H19: #VALUE! | I19: 50 mL | J19: Velvet | K19: Mix de canales | L19: 1 | M19: MUC | N19: https://www.maccosmetics.com.mx/product/13847/119586/productos/maquillaje/rostro/bases-de-maquillaje/studio-radiance-serum-poweredtm-foundation?shade=NW30 | O19: MAKEUP | P19: 6.95 | Q19: RMB | R19: 10000 | S19: =+P19*$T$29 -> #VALUE! | T19: =+S19*0.25 -> #VALUE! | U19: =(S19+T19)*0.044 -> #VALUE! | V19: =S19+T19+U19 -> #VALUE! | W19: 249 | X19: =W19/1.16 -> 214.65517 | Y19: =X19*0.6 -> 128.7931 | Z19: =V19/Y19 -> #VALUE! | AA19: =1-(V19/Y19) -> #VALUE! | AB19: =1-(Y19/(W19/1.16)) -> 0.4 | AC19: China | AE19: 6 | AF19: 48 | AG19: En revisión de dummy para autorización final | AH19: 46341 | AL19: 161.85 | AM19: =+AL19/1.16 -> 139.52586 | AN19: =+V20/AM19 -> #VALUE! | AO19: =1-V20/AM19 -> #VALUE! | AP19: =1-(AM19/(AL19/1.16)) -> 0 | BA19: 1 | BB19: 1 | BC19: 1 | BD19: 1 | BE19: 1 | BF19: 1 | BG19: 1 | BJ19: 9 | BK19: =SUM(BA19:BI19) -> 7 | BL19: =+BK19/BJ19 -> 0.77777778 | BR19: PPEDIDOS-260727498 Se espera que PT este listo 30 Sept | BS19: 46376 | BT19: Eduardo (Compras) | CJ19: 46188
A20: 4 | B20: TBC | C20: Diciembre | D20: En tiempo | E20: 7502327990888 | F20: VLT-04 | G20: Base de Maquillaje Velvet "Smooth Foundation - MN4" | H20: #VALUE! | I20: 50 mL | J20: Velvet | K20: Mix de canales | L20: 1 | M20: MUC | N20: https://www.maccosmetics.com.mx/product/13847/119586/productos/maquillaje/rostro/bases-de-maquillaje/studio-radiance-serum-poweredtm-foundation?shade=NW35 | O20: MAKEUP | P20: 6.95 | Q20: RMB | R20: 10000 | S20: =+P20*$T$29 -> #VALUE! | T20: =+S20*0.25 -> #VALUE! | U20: =(S20+T20)*0.044 -> #VALUE! | V20: =S20+T20+U20 -> #VALUE! | W20: 249 | X20: =W20/1.16 -> 214.65517 | Y20: =X20*0.6 -> 128.7931 | Z20: =V20/Y20 -> #VALUE! | AA20: =1-(V20/Y20) -> #VALUE! | AB20: =1-(Y20/(W20/1.16)) -> 0.4 | AC20: China | AE20: 6 | AF20: 48 | AG20: En revisión de dummy para autorización final | AH20: 46341 | AL20: 161.85 | AM20: =+AL20/1.16 -> 139.52586 | AN20: =+V21/AM20 -> #VALUE! | AO20: =1-V21/AM20 -> #VALUE! | AP20: =1-(AM20/(AL20/1.16)) -> 0 | BA20: 1 | BB20: 1 | BC20: 1 | BD20: 1 | BE20: 1 | BF20: 1 | BG20: 1 | BJ20: 9 | BK20: =SUM(BA20:BI20) -> 7 | BL20: =+BK20/BJ20 -> 0.77777778 | BR20: PPEDIDOS-260727498 Se espera que PT este listo 30 Sept | BS20: 46376 | BT20: Eduardo (Compras) | CJ20: 46188
A21: 5 | B21: TBC | C21: Diciembre | D21: En tiempo | E21: 7502327990895 | F21: VLT-05 | G21: Base de Maquillaje Velvet "Smooth Foundation - MC5" | H21: #VALUE! | I21: 50 mL | J21: Velvet | K21: Mix de canales | L21: 1 | M21: MUC | N21: https://www.maccosmetics.com.mx/product/13847/119586/productos/maquillaje/rostro/bases-de-maquillaje/studio-radiance-serum-poweredtm-foundation?shade=NC42 | O21: MAKEUP | P21: 6.95 | Q21: RMB | R21: 10000 | S21: =+P21*$T$29 -> #VALUE! | T21: =+S21*0.25 -> #VALUE! | U21: =(S21+T21)*0.044 -> #VALUE! | V21: =S21+T21+U21 -> #VALUE! | W21: 249 | X21: =W21/1.16 -> 214.65517 | Y21: =X21*0.6 -> 128.7931 | Z21: =V21/Y21 -> #VALUE! | AA21: =1-(V21/Y21) -> #VALUE! | AB21: =1-(Y21/(W21/1.16)) -> 0.4 | AC21: China | AE21: 6 | AF21: 48 | AG21: En revisión de dummy para autorización final | AH21: 46341 | AL21: 161.85 | AM21: =+AL21/1.16 -> 139.52586 | AN21: =+V22/AM21 -> #VALUE! | AO21: =1-V22/AM21 -> #VALUE! | AP21: =1-(AM21/(AL21/1.16)) -> 0 | BA21: 1 | BB21: 1 | BC21: 1 | BD21: 1 | BE21: 1 | BF21: 1 | BG21: 1 | BJ21: 9 | BK21: =SUM(BA21:BI21) -> 7 | BL21: =+BK21/BJ21 -> 0.77777778 | BR21: PPEDIDOS-260727498 Se espera que PT este listo 30 Sept | BS21: 46376 | BT21: Eduardo (Compras) | CJ21: 46188
A22: 6 | B22: TBC | C22: Diciembre | D22: En tiempo | E22: 7502327990901 | F22: VLT-06 | G22: Base de Maquillaje Velvet "Smooth Foundation - MN6" | H22: #VALUE! | I22: 50 mL | J22: Velvet | K22: Mix de canales | L22: 1 | M22: MUC | N22: https://www.elpalaciodehierro.com/mac-base-de-maquillaje-studio-fix-fluid-spf-15-nc45-5.3-ml-39786604.html?srsltid=AfmBOood9B2Y0XbWpVOtAuHS2Ge3jaGY5lfhHCdFSZcATb5qKcvOXpk_ | O22: MAKEUP | P22: 6.95 | Q22: RMB | R22: 10000 | S22: =+P22*$T$29 -> #VALUE! | T22: =+S22*0.25 -> #VALUE! | U22: =(S22+T22)*0.044 -> #VALUE! | V22: =S22+T22+U22 -> #VALUE! | W22: 249 | X22: =W22/1.16 -> 214.65517 | Y22: =X22*0.6 -> 128.7931 | Z22: =V22/Y22 -> #VALUE! | AA22: =1-(V22/Y22) -> #VALUE! | AB22: =1-(Y22/(W22/1.16)) -> 0.4 | AC22: China | AE22: 6 | AF22: 48 | AG22: En revisión de dummy para autorización final | AH22: 46341 | AL22: 161.85 | AM22: =+AL22/1.16 -> 139.52586 | AN22: =+V27/AM22 -> #VALUE! | AO22: =1-V27/AM22 -> #VALUE! | AP22: =1-(AM22/(AL22/1.16)) -> 0 | BA22: 1 | BB22: 1 | BC22: 1 | BD22: 1 | BE22: 1 | BF22: 1 | BG22: 1 | BJ22: 9 | BK22: =SUM(BA22:BI22) -> 7 | BL22: =+BK22/BJ22 -> 0.77777778 | BR22: PPEDIDOS-260727498 Se espera que PT este listo 30 Sept | BS22: 46376 | BT22: Eduardo (Compras) | CJ22: 46188
A23: 7 | B23: TBC | C23: Diciembre | D23: En tiempo | E23: 7502327990918 | F23: VLT-07 | G23: Corrector Líquido Velvet "Smooth Concealer - CN1" | I23: 7.5 mL | J23: Velvet | K23: Mix de canales | L23: 1 | M23: USHAS | N23: https://www.maccosmetics.com.mx/product/13844/60430/productos/maquillaje/rostro/correctores/corrector-liquido-studio-fix-24-hour-smooth-wear-concealer?shade=NC15 | O23: MAKEUP | P23: 3 | Q23: RMB | R23: 10000 | S23: =+P23*$T$25 -> 0 | T23: =+S23*0.25 -> 0 | U23: =(S23+T23)*0.0267 -> 0 | V23: =S23+T23+U23 -> 0 | W23: 179 | X23: =W23/1.16 -> 154.31034 | Y23: =X23*0.6 -> 92.586207 | Z23: =V23/Y23 -> 0 | AA23: =1-(V23/Y23) -> 1 | AB23: =1-(Y23/(W23/1.16)) -> 0.4 | AC23: China | AG23: En revisión de dummy para autorización final | AH23: 46366 | BA23: 1 | BB23: 1 | BC23: 1 | BD23: 1 | BE23: 1 | BF23: 1 | BG23: 1 | BJ23: 9 | BK23: =SUM(BA23:BI23) -> 7 | BL23: =+BK23/BJ23 -> 0.77777778 | BR23: PPEDIDOS-260827594 Se espera que PT este listo 09 Nov | BS23: 46038 | BT23: Eduardo (Compras)
A24: 8 | B24: TBC | C24: Diciembre | D24: En tiempo | E24: 7502327990925 | F24: VLT-08 | G24: Corrector Líquido Velvet "Smooth Concealer - CC2" | I24: 7.5 mL | J24: Velvet | K24: Mix de canales | L24: 1 | M24: USHAS | N24: https://www.maccosmetics.com.mx/product/13844/60430/productos/maquillaje/rostro/correctores/corrector-liquido-studio-fix-24-hour-smooth-wear-concealer?shade=NC15 | O24: MAKEUP | P24: 3 | Q24: RMB | R24: 10000 | S24: =+P24*$T$25 -> 0 | T24: =+S24*0.25 -> 0 | U24: =(S24+T24)*0.0267 -> 0 | V24: =S24+T24+U24 -> 0 | W24: 179 | X24: =W24/1.16 -> 154.31034 | Y24: =X24*0.6 -> 92.586207 | Z24: =V24/Y24 -> 0 | AA24: =1-(V24/Y24) -> 1 | AB24: =1-(Y24/(W24/1.16)) -> 0.4 | AC24: China | AG24: En revisión de dummy para autorización final | AH24: 46366 | BA24: 1 | BB24: 1 | BC24: 1 | BD24: 1 | BE24: 1 | BF24: 1 | BG24: 1 | BJ24: 9 | BK24: =SUM(BA24:BI24) -> 7 | BL24: =+BK24/BJ24 -> 0.77777778 | BR24: PPEDIDOS-260827594 Se espera que PT este listo 09 Nov | BS24: 46038 | BT24: Eduardo (Compras)
A25: 9 | B25: TBC | C25: Diciembre | D25: En tiempo | E25: 7502327990932 | F25: VLT-09 | G25: Corrector Líquido Velvet "Smooth Concealer - CC3" | I25: 7.5 mL | J25: Velvet | K25: Mix de canales | L25: 1 | M25: USHAS | N25: https://www.maccosmetics.com.mx/product/13844/60430/productos/maquillaje/rostro/correctores/corrector-liquido-studio-fix-24-hour-smooth-wear-concealer?shade=NC15 | O25: MAKEUP | P25: 3 | Q25: RMB | R25: 10000 | S25: =+P25*$T$25 -> 0 | T25: =+S25*0.25 -> 0 | U25: =(S25+T25)*0.0267 -> 0 | V25: =S25+T25+U25 -> 0 | W25: 179 | X25: =W25/1.16 -> 154.31034 | Y25: =X25*0.6 -> 92.586207 | Z25: =V25/Y25 -> 0 | AA25: =1-(V25/Y25) -> 1 | AB25: =1-(Y25/(W25/1.16)) -> 0.4 | AC25: China | AG25: En revisión de dummy para autorización final | AH25: 46366 | BA25: 1 | BB25: 1 | BC25: 1 | BD25: 1 | BE25: 1 | BF25: 1 | BG25: 1 | BJ25: 9 | BK25: =SUM(BA25:BI25) -> 7 | BL25: =+BK25/BJ25 -> 0.77777778 | BR25: PPEDIDOS-260827594 Se espera que PT este listo 09 Nov | BS25: 46038 | BT25: Eduardo (Compras)
A26: 10 | B26: TBC | C26: Diciembre | D26: En tiempo | E26: 7502327990949 | F26: VLT-10 | G26: Corrector Líquido Velvet "Smooth Concealer - MC4" | I26: 7.5 mL | J26: Velvet | K26: Mix de canales | L26: 1 | M26: USHAS | N26: https://www.maccosmetics.com.mx/product/13844/60430/productos/maquillaje/rostro/correctores/corrector-liquido-studio-fix-24-hour-smooth-wear-concealer?shade=NC15 | O26: MAKEUP | P26: 3 | Q26: RMB | R26: 10000 | S26: =+P26*$T$25 -> 0 | T26: =+S26*0.25 -> 0 | U26: =(S26+T26)*0.0267 -> 0 | V26: =S26+T26+U26 -> 0 | W26: 179 | X26: =W26/1.16 -> 154.31034 | Y26: =X26*0.6 -> 92.586207 | Z26: =V26/Y26 -> 0 | AA26: =1-(V26/Y26) -> 1 | AB26: =1-(Y26/(W26/1.16)) -> 0.4 | AC26: China | AG26: En revisión de dummy para autorización final | AH26: 46366 | BA26: 1 | BB26: 1 | BC26: 1 | BD26: 1 | BE26: 1 | BF26: 1 | BG26: 1 | BJ26: 9 | BK26: =SUM(BA26:BI26) -> 7 | BL26: =+BK26/BJ26 -> 0.77777778 | BR26: PPEDIDOS-260827594 Se espera que PT este listo 09 Nov | BS26: 46038 | BT26: Eduardo (Compras)
A27: 11 | B27: TBC | C27: Diciembre | D27: En tiempo | E27: 7502327990956 | F27: VLT-11 | G27: Rubor en crema Velvet "Blush Mauve" | H27: #VALUE! | I27: 5.8 g | J27: Velvet | K27: Mix de canales | L27: 1 | M27: MUC | N27: https://www.rhodeskin.com/products/pocket-blush-tan-line?_pos=1&_psq=blush&_ss=e&_v=1.0 | O27: MAKEUP | P27: 4.75 | Q27: RMB | R27: 10000 | S27: =+P27*$T$29 -> #VALUE! | T27: =+S27*0.25 -> #VALUE! | U27: =(S27+T27)*0.0257 -> #VALUE! | V27: =S27+T27+U27 -> #VALUE! | W27: 169 | X27: =W27/1.16 -> 145.68966 | Y27: =X27*0.6 -> 87.413793 | Z27: =V27/Y27 -> #VALUE! | AA27: =1-(V27/Y27) -> #VALUE! | AB27: =1-(Y27/(W27/1.16)) -> 0.4 | AC27: China | AE27: 6 | AF27: 144 | AG27: En revisión de dummy para autorización final | AH27: 46341 | AL27: 109.85 | AM27: =+AL27/1.16 -> 94.698276 | AN27: =+V28/AM27 -> #VALUE! | AO27: =1-V28/AM27 -> #VALUE! | AP27: =1-(AM27/(AL27/1.16)) -> 0 | BA27: 1 | BB27: 1 | BC27: 1 | BD27: 1 | BE27: 1 | BF27: 1 | BG27: 1 | BJ27: 9 | BK27: =SUM(BA27:BI27) -> 7 | BL27: =+BK27/BJ27 -> 0.77777778 | BR27: PPEDIDOS-260727520 Se espera que PT este listo 14 Octubre | BS27: 46379 | BT27: Eduardo (Compras) | CJ27: 46188
A28: 12 | B28: TBC | C28: Diciembre | D28: En tiempo | E28: 7502327990963 | F28: VLT-12 | G28: Rubor en crema Velvet "Blush Peony" | H28: #VALUE! | I28: 5.8 g | J28: Velvet | K28: Mix de canales | L28: 1 | M28: MUC | N28: https://www.rhodeskin.com/products/pocket-blush-tan-line?_pos=1&_psq=blush&_ss=e&_v=1.1 | O28: MAKEUP | P28: 4.75 | Q28: RMB | R28: 10000 | S28: =+P28*$T$29 -> #VALUE! | T28: =+S28*0.25 -> #VALUE! | U28: =(S28+T28)*0.0257 -> #VALUE! | V28: =S28+T28+U28 -> #VALUE! | W28: 169 | X28: =W28/1.16 -> 145.68966 | Y28: =X28*0.6 -> 87.413793 | Z28: =V28/Y28 -> #VALUE! | AA28: =1-(V28/Y28) -> #VALUE! | AB28: =1-(Y28/(W28/1.16)) -> 0.4 | AC28: China | AE28: 6 | AF28: 144 | AG28: En revisión de dummy para autorización final | AH28: 46341 | AL28: 109.85 | AM28: =+AL28/1.16 -> 94.698276 | AN28: =+V29/AM28 -> #VALUE! | AO28: =1-V29/AM28 -> #VALUE! | AP28: =1-(AM28/(AL28/1.16)) -> 0 | BA28: 1 | BB28: 1 | BC28: 1 | BD28: 1 | BE28: 1 | BF28: 1 | BG28: 1 | BJ28: 9 | BK28: =SUM(BA28:BI28) -> 7 | BL28: =+BK28/BJ28 -> 0.77777778 | BR28: PPEDIDOS-260727520 Se espera que PT este listo 14 Octubre | BS28: 46379 | BT28: Eduardo (Compras) | CJ28: 46188
